{
  "comments": [
    {
      "unresolved": false,
      "key": {
        "uuid": "c00220fe_9a0d4f9a",
        "filename": "/PATCHSET_LEVEL",
        "patchSetId": 4
      },
      "lineNbr": 0,
      "author": {
        "id": 1003247
      },
      "writtenOn": "2022-10-28T14:28:53Z",
      "side": 1,
      "message": "b/256134772 shows failure on GSI R\n\n\u003d\u003d\u003d\u003d\u003d\u003d\u003d\u003d\u003d\u003d\u003d\u003d\u003d\u003d\u003d\u003d\u003d\u003d\u003d\u003d\u003d\u003d\u003d\u003d\u003d\u003d\u003d\u003d\u003d\u003d\u003d\u003d\u003d\u003d\u003d\u003d\u003d\u003d\u003d\u003d\u003d\u003d\u003d\u003d\u003d\u003d\u003d\u003d\u003d\u003d\u003d\u003d\u003d\u003d\u003d\u003d\u003d\u003d\u003d\u003d\u003d\u003d\u003d\u003d\u003d\u003d\u003d\u003d\u003d\u003d\nERROR: testAllowedCongestionControl (sysctls_test.SysctlsTest)\n----------------------------------------------------------------------\nTraceback (most recent call last):\n  File \"/data/local/tmp/vts_kernel_net_tests/kernel_net_tests_bin/sysctls_test.py\", line 33, in testAllowedCongestionControl\n    self.check(\u0027/proc/sys/net/ipv4/tcp_allowed_congestion_control\u0027)\n  File \"/data/local/tmp/vts_kernel_net_tests/kernel_net_tests_bin/sysctls_test.py\", line 25, in check\n    algs \u003d open(f).readline().strip().split(\u0027 \u0027)\nIOError: [Errno 2] No such file or directory: \u0027/proc/sys/net/ipv4/tcp_allowed_congestion_control\u0027\n\n\u003d\u003d\u003d\u003d\u003d\u003d\u003d\u003d\u003d\u003d\u003d\u003d\u003d\u003d\u003d\u003d\u003d\u003d\u003d\u003d\u003d\u003d\u003d\u003d\u003d\u003d\u003d\u003d\u003d\u003d\u003d\u003d\u003d\u003d\u003d\u003d\u003d\u003d\u003d\u003d\u003d\u003d\u003d\u003d\u003d\u003d\u003d\u003d\u003d\u003d\u003d\u003d\u003d\u003d\u003d\u003d\u003d\u003d\u003d\u003d\u003d\u003d\u003d\u003d\u003d\u003d\u003d\u003d\u003d\u003d\nERROR: testAvailableCongestionControl (sysctls_test.SysctlsTest)\n----------------------------------------------------------------------\nTraceback (most recent call last):\n  File \"/data/local/tmp/vts_kernel_net_tests/kernel_net_tests_bin/sysctls_test.py\", line 36, in testAvailableCongestionControl\n    self.check(\u0027/proc/sys/net/ipv4/tcp_available_congestion_control\u0027)\n  File \"/data/local/tmp/vts_kernel_net_tests/kernel_net_tests_bin/sysctls_test.py\", line 25, in check\n    algs \u003d open(f).readline().strip().split(\u0027 \u0027)\nIOError: [Errno 2] No such file or directory: \u0027/proc/sys/net/ipv4/tcp_available_congestion_control\u0027\n\n----------------------------------------------------------------------",
      "revId": "65eadca7f699acb41003081a9461b7249a5a78e9",
      "serverId": "85c56323-6fa9-3386-8a01-6480fb634889"
    }
  ]
}