{
  "comments": [
    {
      "unresolved": true,
      "key": {
        "uuid": "70890a08_44d4803f",
        "filename": "net/test/multinetwork_base.py",
        "patchSetId": 3
      },
      "lineNbr": 141,
      "author": {
        "id": 1101726
      },
      "writtenOn": "2024-02-09T06:24:54Z",
      "side": 1,
      "message": "This doesn\u0027t actually work because the code calls with larger netIds.\n```\nValueError: 64552 is not in list\n```",
      "range": {
        "startLine": 141,
        "startChar": 0,
        "endLine": 141,
        "endChar": 33
      },
      "revId": "ac2f390b3793d48386ae42516e4281ad4df4bd63",
      "serverId": "85c56323-6fa9-3386-8a01-6480fb634889"
    }
  ]
}